<?xml version="1.0"?>

<robot xmlns:xacro="http://www.ros.org/wiki/xacro" name="puc1_robot">

  <xacro:include filename="$(find puc1_description)/urdf/puc1_robot.gazebo" />
  <!-- <xacro:include filename="$(find puc1_description)/urdf/materials.xacro" /> -->

  <xacro:property name="cameraSize" value="0.05"/>
  <xacro:property name="cameraMass" value="0.1"/>



  <!-- Base Robotic -->
  <link name="base_link">
    <inertial>
      <mass value="2" />
      <origin xyz="0 0 0.1" />
      <inertia ixx="0.01" ixy="0.0" ixz="0.0"
        iyy="0.01" iyz="0.0" izz="0.5" />
    </inertial>

      <visual>
        <origin xyz="0 0 0" rpy="0 0 0" />
        <geometry>
          <cylinder length="0.02" radius="0.2245"/>
        </geometry>
        <material name ="White" />
      </visual>

      <collision>
        <origin xyz="0 0 0" rpy="0 0 0" />
        <geometry>
          <cylinder length="0.02" radius="0.2245"/>
        </geometry>
      </collision>
  </link>


  <!-- Roda Castor Frontal -->
  <link name="front_caster">
    <inertial>
      <mass value="0.001" />
      <origin xyz="0 0 0" />
      <inertia ixx="0.0001" ixy="0.0" ixz="0.0"
          iyy="0.0001" iyz="0.0"
          izz="0.0001" />
    </inertial>

      <visual>
        <origin xyz="0 0 0" rpy="-1.5707 0 1.5707" />
        <geometry>
          <mesh filename="package://puc1_description/meshes/castor.dae"/>
        </geometry>
        <material name ="light_grey">
          <color rgba="0.6 0.6 0.6 1"/>
        </material>
      </visual>

      <collision>
        <origin xyz="0 0 0" rpy="-1.5707 0 1.5707" />
        <geometry>
          <cylinder length="0.0605" radius="0.097"/>
        </geometry>
      </collision>
  </link>

  <joint name="front_caster_joint" type="fixed">
    <origin xyz="0.18745 0 -0.00475" rpy="0 0 0" />
    <parent link="base_link" />
    <child link="front_caster" />
  </joint>  


  <!-- Roda Castor Traseira -->
  <link name="rear_caster">
    <inertial>
      <mass value="0.001" />
      <origin xyz="0 0 0" />
      <inertia ixx="0.0001" ixy="0.0" ixz="0.0"
        iyy="0.0001" iyz="0.0"
        izz="0.0001" />
      </inertial>

      <visual>
        <origin xyz="0 0 0" rpy="-1.5707 0 1.5707" />
        <geometry>
          <mesh filename="package://puc1_description/meshes/castor.dae"/>
        </geometry>
        <material name ="light_grey">
          <color rgba="0.6 0.6 0.6 1"/>
        </material>
      </visual>

      <collision>
        <origin xyz="0 0 0" rpy="-1.5707 0 1.5707" />
        <geometry>
          <cylinder length="0.0605" radius="0.097"/>
        </geometry>
      </collision>
  </link>

  <joint name="rear_caster_joint" type="fixed">
    <origin xyz="-0.18745 0 -0.00475" rpy="0 0 0" />
    <parent link="base_link" />
    <child link="rear_caster" />
  </joint>


  <!-- Roda Direita -->
  <link name="right_wheel_link">
    <inertial>
      <origin xyz="0 0 0" rpy="0 1.5707 1.5707"/>
      <mass value="0.01" />
      <inertia ixx="0.001" ixy="0.0" ixz="0.0"
        iyy="0.001" iyz="0.0" izz="0.001" />
      </inertial>

      <visual>
        <origin xyz="0 0 0" rpy="0 1.5707 1.5707" />
        <geometry>
          <cylinder radius="0.10182" length = "0.04"/>
        </geometry>
        <material name ="black" />
      </visual>

      <collision>
        <origin xyz="0 0 0" rpy="0 1.5707 1.5707" />
        <geometry>
          <cylinder radius="0.10182" length = "0.04"/>
        </geometry>
      </collision>
  </link>

  <joint name="right_wheel_joint" type="continuous">
    <origin xyz="0 -0.2445 0" rpy="0 0 0"/>
    <parent link="base_link"/>
    <child link="right_wheel_link"/>
    <axis xyz="0 1 0"/>
  </joint>


  <!-- Roda Esquerda -->
  <link name="left_wheel_link">
    <inertial>
      <origin xyz="0 0 0" rpy="0 1.5707 1.5707"/>
      <mass value="0.01" />
      <inertia ixx="0.001" ixy="0.0" ixz="0.0"
        iyy="0.001" iyz="0.0" izz="0.001" />
      </inertial>

      <visual>
        <origin xyz="0 0 0" rpy="0 1.5707 1.5707" />
        <geometry>
          <cylinder radius="0.10182" length = "0.04"/>
        </geometry>
        <material name ="black" />
      </visual>

      <collision>
        <origin xyz="0 0 0" rpy="0 1.5707 1.5707" />
        <geometry>
          <cylinder radius="0.10182" length = "0.04"/>
        </geometry>
      </collision>
  </link>

  <joint name="left_wheel_joint" type="continuous">
    <origin xyz="0 0.2445 0" rpy="0 0 0"/>
    <parent link="base_link"/>
    <child link="left_wheel_link"/>
    <axis xyz="0 1 0"/>
  </joint>


  <!-- Torre do Rplidar Laser -->
  <link name="laser_tower">
    <inertial>
      <mass value="0.001" />
      <origin xyz="0 0 0" />
      <inertia ixx="0.0001" ixy="0.0" ixz="0.0"
        iyy="0.0001" iyz="0.0"
        izz="0.0001" />
    </inertial>

      <visual>
        <origin xyz="0 0 0" rpy="0 0 0" />
        <geometry>
          <cylinder length="0.2" radius="0.03"/>
        </geometry>
        <material name ="White" />
      </visual>

      <collision>
        <origin xyz="0 0 0" rpy="0 0 0" />
        <geometry>
          <cylinder length="0.02" radius="0.03"/>
        </geometry>
      </collision>
  </link>

  <joint name="laser_tower_joint" type="fixed">
    <origin xyz="0 0 0.11" rpy="0 0 0" />
    <parent link="base_link" />
    <child link="laser_tower" />
  </joint>


  <!-- Rplidar Laser -->
  <link name="base_laser">
    <collision>
      <origin xyz="0 0 0" rpy="0 0 0"/>
      <geometry>
        <box size="0.1 0.1 0.1"/>
      </geometry>
    </collision>

    <visual>
      <origin xyz="0 0 0" rpy="0 0 0"/>
      <geometry>
        <mesh filename="package://puc1_description/meshes/rplidar.stl" scale="0.01 0.01 0.01" />
      </geometry>
    </visual>

    <inertial>
      <mass value="1e-5" />
      <origin xyz="0 0 0" rpy="0 0 0"/>
      <inertia ixx="1e-6" ixy="0" ixz="0" iyy="1e-6" iyz="0" izz="1e-6" />
    </inertial>
  </link>

  <joint name="laser_joint" type="fixed">
    <axis xyz="0 1 0" />
    <origin xyz=".0 0 0.1" rpy="0 0 0"/>
    <parent link="laser_tower"/>
    <child link="base_laser"/>
  </joint>


  <!-- Camera1 -->
  <link name="camera1">
    <collision>
      <origin xyz="0 0 0" rpy="0 0 0"/>
      <geometry>
        <box size="${cameraSize} ${cameraSize} ${cameraSize}"/>
      </geometry>
    </collision>

    <visual>
      <origin xyz="0 0 0" rpy="0 0 0"/>
      <geometry>
        <box size="${cameraSize} ${cameraSize} ${cameraSize}"/>
      </geometry>
    </visual>

    <inertial>
      <mass value="${cameraMass}" />
      <origin xyz="0 0 0" rpy="0 0 0"/>
      <box_inertia m="${cameraMass}" x="${cameraSize}" y="${cameraSize}" z="${cameraSize}" />
      <inertia ixx="1e-6" ixy="0" ixz="0" iyy="1e-6" iyz="0" izz="1e-6" />
    </inertial>
  </link>

  <joint name="camera1_joint" type="fixed">
    <axis xyz="0 1 0" />
    <origin xyz=".1995 0 0.035" rpy="0 0 0"/>
    <parent link="base_link"/>
    <child link="camera1"/>
  </joint>


  <!-- Camera2 -->
  <link name="camera2">
    <collision>
      <origin xyz="0 0 0" rpy="0 0 0"/>
      <geometry>
        <box size="${cameraSize} ${cameraSize} ${cameraSize}"/>
      </geometry>
    </collision>

    <visual>
      <origin xyz="0 0 0" rpy="0 0 0"/>
      <geometry>
        <box size="${cameraSize} ${cameraSize} ${cameraSize}"/>
      </geometry>
    </visual>

    <inertial>
      <mass value="${cameraMass}" />
      <origin xyz="0 0 0" rpy="0 0 0"/>
      <box_inertia m="${cameraMass}" x="${cameraSize}" y="${cameraSize}" z="${cameraSize}" />
      <inertia ixx="1e-6" ixy="0" ixz="0" iyy="1e-6" iyz="0" izz="1e-6" />
    </inertial>
  </link>

  <joint name="camera2_joint" type="fixed">
    <axis xyz="0 1 0" />
    <origin xyz="-0.1995 0 0.035" rpy="0 0 3.14159265"/>
    <parent link="base_link"/>
    <child link="camera2"/>
  </joint>

  

</robot>